<mujoco model="MuJoCo Model">
    <compiler angle="radian" coordinate="local"/>
    <default>
        <default class="active_adhesion">
        <geom rgba=".8 .5 .5 1" margin=".01" gap=".01"/>
        </default>
    </default>
    <option timestep="0.005" />
    <option>
        <flag multiccd="enable"/>
    </option>
    <size njmax="500" nconmax="100" />
    <worldbody>
        <geom name="floor0" size="2.5 2.5 1" pos="2.5 2.5 0" type="plane" />
        <body name="floor0" pos="2.5 2.5 0">
            <inertial pos="2.5 2.5 0" mass="0" diaginertia="0 0 0" />
            <site name="target" pos="0 0 0.05" size="0.1" rgba="0 0 1 1" />
        </body>
        <body name="wall1" pos="0.005 2.5 0.3125">
            <inertial pos="0 0 0" mass="31.25" diaginertia="66.1214 1.01751 65.1044" />
            <geom name="wall1" size="0.005 2.5 0.3125" type="box" margin=".05" gap=".05"/>
        </body>
        <body name="wall2" pos="4.995 2.5 0.3125">
            <inertial pos="0 0 0" mass="31.25" diaginertia="66.1214 1.01751 65.1044" />
            <geom name="wall2" size="0.005 2.5 0.3125" type="box" margin=".05" gap=".05"/>
        </body>
        <body name="wall3" pos="2.5 0.005 0.3125">
            <inertial pos="0 0 0" mass="31.125" diaginertia="1.01344 65.3392 64.3263" />
            <geom name="wall3" size="2.49 0.005 0.3125" type="box" margin=".05" gap=".05"/>
        </body>
        <body name="wall4" pos="2.5 4.995 0.3125">
            <inertial pos="0 0 0" mass="31.125" diaginertia="1.01344 65.3392 64.3263" />
            <geom name="wall4" size="2.49 0.005 0.3125" type="box" margin=".05" gap=".05"/>
        </body>
        <!-- <body name="particle_hinge0:particle" pos="0.55 0.55 0.15" childclass="active_adhesion"> -->
        <body name="particle_hinge0:particle" pos="0.55 0.55 0.15">
            <joint name="particle_hinge0:tx" pos="0 0 0" axis="1 0 0" type="slide" damping="10" />
            <joint name="particle_hinge0:ty" pos="0 0 0" axis="0 1 0" type="slide" damping="10" />
            <joint name="particle_hinge0:tz" pos="0 0 0" axis="0 0 1" type="slide" damping="10000" />
            <joint name="particle_hinge0:rz" pos="0 0 0" axis="0 0 1" damping="10" />
            <geom name="particle_hinge0:agent" size="0.15" quat="0.707388 0.706825 0 0" rgba="1 0 0 1" condim="1" priority="2" margin="0.01" gap="0.01"/>
            <!-- <geom name="particle_hinge0:agent" size="0.15" quat="0.707388 0.706825 0 0" rgba="1 0 0 1"/> -->
            <geom name="particle_hinge0:arm1" size="0.05" pos="-0.13 -0.075 -0.05" quat="0.707388 0.706825 0 0" rgba="1 0 0 1"/>
            <geom name="particle_hinge0:arm2" size="0.05" pos="0.13 -0.075 -0.05" quat="0.707388 0.706825 0 0" rgba="1 0 0 1"/>
            <site name="player" pos="0 0 0" size="0.1" rgba="0 0 1 1" />
        </body>
        <body name="cube0" pos="0.75 0.75 0.125">
            <joint name="cube0:slide0" pos="0 0 0" axis="1 0 0" type="slide" damping="0.01" />
            <joint name="cube0:slide1" pos="0 0 0" axis="0 1 0" type="slide" damping="0.01" />
            <joint name="cube0:slide2" pos="0 0 0" axis="0 0 1" type="slide" damping="0.01" />
            <geom name="cube0" size="0.125 0.125 0.125" type="box" condim="1" mass="0.05"/>
            <site name="cube0" pos="0 0 0" size="0.1" rgba="0 0 1 1" />
        </body>
        <body name="cube1" pos="0.9 3.8 0.125">
            <joint name="cube1:slide0" pos="0 0 0" axis="1 0 0" type="slide" damping="0.01" />
            <joint name="cube1:slide1" pos="0 0 0" axis="0 1 0" type="slide" damping="0.01" />
            <joint name="cube1:slide2" pos="0 0 0" axis="0 0 1" type="slide" damping="0.01" />
            <geom name="cube1" size="0.125 0.125 0.125" type="box" condim="1" mass="0.05"/>
            <site name="cube1" pos="0 0 0" size="0.1" rgba="0 0 1 1" />
        </body>
        <body name="cube2" pos="4.1 2.0 0.125">
            <joint name="cube2:slide0" pos="0 0 0" axis="1 0 0" type="slide" damping="0.01" />
            <joint name="cube2:slide1" pos="0 0 0" axis="0 1 0" type="slide" damping="0.01" />
            <joint name="cube2:slide2" pos="0 0 0" axis="0 0 1" type="slide" damping="0.01" />
            <geom name="cube2" size="0.125 0.125 0.125" type="box" condim="1" mass="0.05"/>
            <site name="cube2" pos="0 0 0" size="0.1" rgba="0 0 1 1" />
        </body>
        <body name="cube3" pos="3.9 3.9 0.125">
            <joint name="cube3:slide0" pos="0 0 0" axis="1 0 0" type="slide" damping="0.01" />
            <joint name="cube3:slide1" pos="0 0 0" axis="0 1 0" type="slide" damping="0.01" />
            <joint name="cube3:slide2" pos="0 0 0" axis="0 0 1" type="slide" damping="0.01" />
            <geom name="cube3" size="0.125 0.125 0.125" type="box" condim="1" mass="0.05"/>
            <site name="cube3" pos="0 0 0" size="0.1" rgba="0 0 1 1" />
        </body>
    </worldbody>
    <actuator>
        <general name="particle_hinge0:motortx" joint="particle_hinge0:tx" gear="100 0 0 0 0 0" ctrllimited="true" ctrlrange="-10 10"/>
        <general name="particle_hinge0:motorty" joint="particle_hinge0:ty" gear="100 0 0 0 0 0" ctrllimited="true" ctrlrange="-10 10"/>
        <general name="particle_hinge0:motorrz" joint="particle_hinge0:rz" gear="100 0 0 0 0 0" ctrllimited="true" ctrlrange="-10 10"/>
    </actuator>
</mujoco>
